2020-04-03 01:04:49,611 ERROR: Exception on /register [POST] [in /usr/local/lib/python3.6/dist-packages/flask/app.py:1891]
Traceback (most recent call last):
  File "/usr/local/lib/python3.6/dist-packages/sqlalchemy/engine/base.py", line 1248, in _execute_context
    cursor, statement, parameters, context
  File "/usr/local/lib/python3.6/dist-packages/sqlalchemy/engine/default.py", line 588, in do_execute
    cursor.execute(statement, parameters)
  File "/home/ubuntu/.local/lib/python3.6/site-packages/pymysql/cursors.py", line 170, in execute
    result = self._query(query)
  File "/home/ubuntu/.local/lib/python3.6/site-packages/pymysql/cursors.py", line 328, in _query
    conn.query(q)
  File "/home/ubuntu/.local/lib/python3.6/site-packages/pymysql/connections.py", line 517, in query
    self._affected_rows = self._read_query_result(unbuffered=unbuffered)
  File "/home/ubuntu/.local/lib/python3.6/site-packages/pymysql/connections.py", line 732, in _read_query_result
    result.read()
  File "/home/ubuntu/.local/lib/python3.6/site-packages/pymysql/connections.py", line 1075, in read
    first_packet = self.connection._read_packet()
  File "/home/ubuntu/.local/lib/python3.6/site-packages/pymysql/connections.py", line 684, in _read_packet
    packet.check_error()
  File "/home/ubuntu/.local/lib/python3.6/site-packages/pymysql/protocol.py", line 220, in check_error
    err.raise_mysql_exception(self._data)
  File "/home/ubuntu/.local/lib/python3.6/site-packages/pymysql/err.py", line 109, in raise_mysql_exception
    raise errorclass(errno, errval)
pymysql.err.ProgrammingError: (1146, "Table 'barhopper.user' doesn't exist")

The above exception was the direct cause of the following exception:

Traceback (most recent call last):
  File "/usr/local/lib/python3.6/dist-packages/flask/app.py", line 2446, in wsgi_app
    response = self.full_dispatch_request()
  File "/usr/local/lib/python3.6/dist-packages/flask/app.py", line 1951, in full_dispatch_request
    rv = self.handle_user_exception(e)
  File "/usr/local/lib/python3.6/dist-packages/flask/app.py", line 1820, in handle_user_exception
    reraise(exc_type, exc_value, tb)
  File "/usr/local/lib/python3.6/dist-packages/flask/_compat.py", line 39, in reraise
    raise value
  File "/usr/local/lib/python3.6/dist-packages/flask/app.py", line 1949, in full_dispatch_request
    rv = self.dispatch_request()
  File "/usr/local/lib/python3.6/dist-packages/flask/app.py", line 1935, in dispatch_request
    return self.view_functions[rule.endpoint](**req.view_args)
  File "/home/ubuntu/notebooks/barhopper/barHopper/app/routes.py", line 55, in register
    if form.validate_on_submit():
  File "/usr/local/lib/python3.6/dist-packages/flask_wtf/form.py", line 100, in validate_on_submit
    return self.is_submitted() and self.validate()
  File "/usr/local/lib/python3.6/dist-packages/wtforms/form.py", line 310, in validate
    return super(Form, self).validate(extra)
  File "/usr/local/lib/python3.6/dist-packages/wtforms/form.py", line 152, in validate
    if not field.validate(self, extra):
  File "/usr/local/lib/python3.6/dist-packages/wtforms/fields/core.py", line 206, in validate
    stop_validation = self._run_validation_chain(form, chain)
  File "/usr/local/lib/python3.6/dist-packages/wtforms/fields/core.py", line 226, in _run_validation_chain
    validator(form, self)
  File "/home/ubuntu/notebooks/barhopper/barHopper/app/forms.py", line 26, in validate_username
    user = User.query.filter_by(username=username.data).first()
  File "/usr/local/lib/python3.6/dist-packages/sqlalchemy/orm/query.py", line 3298, in first
    ret = list(self[0:1])
  File "/usr/local/lib/python3.6/dist-packages/sqlalchemy/orm/query.py", line 3076, in __getitem__
    return list(res)
  File "/usr/local/lib/python3.6/dist-packages/sqlalchemy/orm/query.py", line 3403, in __iter__
    return self._execute_and_instances(context)
  File "/usr/local/lib/python3.6/dist-packages/sqlalchemy/orm/query.py", line 3428, in _execute_and_instances
    result = conn.execute(querycontext.statement, self._params)
  File "/usr/local/lib/python3.6/dist-packages/sqlalchemy/engine/base.py", line 984, in execute
    return meth(self, multiparams, params)
  File "/usr/local/lib/python3.6/dist-packages/sqlalchemy/sql/elements.py", line 293, in _execute_on_connection
    return connection._execute_clauseelement(self, multiparams, params)
  File "/usr/local/lib/python3.6/dist-packages/sqlalchemy/engine/base.py", line 1103, in _execute_clauseelement
    distilled_params,
  File "/usr/local/lib/python3.6/dist-packages/sqlalchemy/engine/base.py", line 1288, in _execute_context
    e, statement, parameters, cursor, context
  File "/usr/local/lib/python3.6/dist-packages/sqlalchemy/engine/base.py", line 1482, in _handle_dbapi_exception
    sqlalchemy_exception, with_traceback=exc_info[2], from_=e
  File "/usr/local/lib/python3.6/dist-packages/sqlalchemy/util/compat.py", line 178, in raise_
    raise exception
  File "/usr/local/lib/python3.6/dist-packages/sqlalchemy/engine/base.py", line 1248, in _execute_context
    cursor, statement, parameters, context
  File "/usr/local/lib/python3.6/dist-packages/sqlalchemy/engine/default.py", line 588, in do_execute
    cursor.execute(statement, parameters)
  File "/home/ubuntu/.local/lib/python3.6/site-packages/pymysql/cursors.py", line 170, in execute
    result = self._query(query)
  File "/home/ubuntu/.local/lib/python3.6/site-packages/pymysql/cursors.py", line 328, in _query
    conn.query(q)
  File "/home/ubuntu/.local/lib/python3.6/site-packages/pymysql/connections.py", line 517, in query
    self._affected_rows = self._read_query_result(unbuffered=unbuffered)
  File "/home/ubuntu/.local/lib/python3.6/site-packages/pymysql/connections.py", line 732, in _read_query_result
    result.read()
  File "/home/ubuntu/.local/lib/python3.6/site-packages/pymysql/connections.py", line 1075, in read
    first_packet = self.connection._read_packet()
  File "/home/ubuntu/.local/lib/python3.6/site-packages/pymysql/connections.py", line 684, in _read_packet
    packet.check_error()
  File "/home/ubuntu/.local/lib/python3.6/site-packages/pymysql/protocol.py", line 220, in check_error
    err.raise_mysql_exception(self._data)
  File "/home/ubuntu/.local/lib/python3.6/site-packages/pymysql/err.py", line 109, in raise_mysql_exception
    raise errorclass(errno, errval)
sqlalchemy.exc.ProgrammingError: (pymysql.err.ProgrammingError) (1146, "Table 'barhopper.user' doesn't exist")
[SQL: SELECT user.id AS user_id, user.username AS user_username, user.email AS user_email, user.password_hash AS user_password_hash 
FROM user 
WHERE user.username = %(username_1)s 
 LIMIT %(param_1)s]
[parameters: {'username_1': 'Shane', 'param_1': 1}]
(Background on this error at: http://sqlalche.me/e/f405)
2020-04-03 01:06:54,983 INFO: Test startup [in /home/ubuntu/notebooks/barhopper/barHopper/app/__init__.py:51]
2020-04-03 01:07:03,846 INFO: Test startup [in /home/ubuntu/notebooks/barhopper/barHopper/app/__init__.py:51]
2020-04-03 01:07:09,214 INFO: Test startup [in /home/ubuntu/notebooks/barhopper/barHopper/app/__init__.py:51]
2020-04-03 01:07:13,252 INFO: Test startup [in /home/ubuntu/notebooks/barhopper/barHopper/app/__init__.py:51]
2020-04-03 01:07:22,506 INFO: Test startup [in /home/ubuntu/notebooks/barhopper/barHopper/app/__init__.py:51]
2020-04-03 01:07:52,448 ERROR: Exception on /user/shane [GET] [in /usr/local/lib/python3.6/dist-packages/flask/app.py:1891]
Traceback (most recent call last):
  File "/usr/local/lib/python3.6/dist-packages/flask/app.py", line 2446, in wsgi_app
    response = self.full_dispatch_request()
  File "/usr/local/lib/python3.6/dist-packages/flask/app.py", line 1951, in full_dispatch_request
    rv = self.handle_user_exception(e)
  File "/usr/local/lib/python3.6/dist-packages/flask/app.py", line 1820, in handle_user_exception
    reraise(exc_type, exc_value, tb)
  File "/usr/local/lib/python3.6/dist-packages/flask/_compat.py", line 39, in reraise
    raise value
  File "/usr/local/lib/python3.6/dist-packages/flask/app.py", line 1949, in full_dispatch_request
    rv = self.dispatch_request()
  File "/usr/local/lib/python3.6/dist-packages/flask/app.py", line 1935, in dispatch_request
    return self.view_functions[rule.endpoint](**req.view_args)
  File "/usr/local/lib/python3.6/dist-packages/flask_login/utils.py", line 272, in decorated_view
    return func(*args, **kwargs)
  File "/home/ubuntu/notebooks/barhopper/barHopper/app/routes.py", line 104, in user
    crawls = user.trips.order_by(Crawl.timestamp.desc()).paginate(
AttributeError: 'User' object has no attribute 'trips'
2020-04-03 01:31:03,010 INFO: Test startup [in /home/ubuntu/notebooks/barhopper/barHopper/app/__init__.py:51]
2020-04-03 01:34:10,309 INFO: Test startup [in /home/ubuntu/notebooks/barhopper/barHopper/app/__init__.py:51]
2020-04-03 02:04:17,317 INFO: Test startup [in /home/ubuntu/notebooks/barhopper/barHopper/app/__init__.py:51]
2020-04-03 02:10:48,636 INFO: Test startup [in /home/ubuntu/notebooks/barhopper/barHopper/app/__init__.py:51]
2020-04-03 02:13:13,706 INFO: Test startup [in /home/ubuntu/notebooks/barhopper/barHopper/app/__init__.py:51]
2020-04-03 16:02:10,334 INFO: Test startup [in /home/ubuntu/notebooks/barhopper/barHopper/app/__init__.py:51]
2020-04-05 00:34:48,473 INFO: Test startup [in /home/ubuntu/notebooks/barhopper/barHopper/app/__init__.py:51]
